Traceback (most recent call last):
  File "manage.py", line 11, in main
    from django.core.management import execute_from_command_line
ModuleNotFoundError: No module named 'django'

The above exception was the direct cause of the following exception:

Traceback (most recent call last):
  File "manage.py", line 22, in <module>
    main()
  File "manage.py", line 13, in main
    raise ImportError(
ImportError: Couldn't import Django. Are you sure it's installed and available on your PYTHONPATH environment variable? Did you forget to activate a virtual environment?
Error in sys.excepthook:
Traceback (most recent call last):
  File "/usr/lib/python3/dist-packages/apport_python_hook.py", line 72, in apport_excepthook
    from apport.fileutils import likely_packaged, get_recent_crashes
  File "/usr/lib/python3/dist-packages/apport/__init__.py", line 5, in <module>
    from apport.report import Report
  File "/usr/lib/python3/dist-packages/apport/report.py", line 32, in <module>
    import apport.fileutils
  File "/usr/lib/python3/dist-packages/apport/fileutils.py", line 12, in <module>
    import os, glob, subprocess, os.path, time, pwd, sys, requests_unixsocket
  File "/usr/lib/python3/dist-packages/requests_unixsocket/__init__.py", line 1, in <module>
    import requests
  File "/usr/lib/python3/dist-packages/requests/__init__.py", line 43, in <module>
    import urllib3
  File "/usr/lib/python3/dist-packages/urllib3/__init__.py", line 7, in <module>
    from .connectionpool import HTTPConnectionPool, HTTPSConnectionPool, connection_from_url
  File "/usr/lib/python3/dist-packages/urllib3/connectionpool.py", line 11, in <module>
    from .exceptions import (
  File "/usr/lib/python3/dist-packages/urllib3/exceptions.py", line 2, in <module>
    from six.moves.http_client import IncompleteRead as httplib_IncompleteRead
ModuleNotFoundError: No module named 'six'

Original exception was:
Traceback (most recent call last):
  File "manage.py", line 11, in main
    from django.core.management import execute_from_command_line
ModuleNotFoundError: No module named 'django'

The above exception was the direct cause of the following exception:

Traceback (most recent call last):
  File "manage.py", line 22, in <module>
    main()
  File "manage.py", line 13, in main
    raise ImportError(
ImportError: Couldn't import Django. Are you sure it's installed and available on your PYTHONPATH environment variable? Did you forget to activate a virtual environment?
Traceback (most recent call last):
  File "manage.py", line 11, in main
    from django.core.management import execute_from_command_line
ModuleNotFoundError: No module named 'django'

The above exception was the direct cause of the following exception:

Traceback (most recent call last):
  File "manage.py", line 22, in <module>
    main()
  File "manage.py", line 13, in main
    raise ImportError(
ImportError: Couldn't import Django. Are you sure it's installed and available on your PYTHONPATH environment variable? Did you forget to activate a virtual environment?
Error in sys.excepthook:
Traceback (most recent call last):
  File "/usr/lib/python3/dist-packages/apport_python_hook.py", line 72, in apport_excepthook
    from apport.fileutils import likely_packaged, get_recent_crashes
  File "/usr/lib/python3/dist-packages/apport/__init__.py", line 5, in <module>
    from apport.report import Report
  File "/usr/lib/python3/dist-packages/apport/report.py", line 32, in <module>
    import apport.fileutils
  File "/usr/lib/python3/dist-packages/apport/fileutils.py", line 12, in <module>
    import os, glob, subprocess, os.path, time, pwd, sys, requests_unixsocket
  File "/usr/lib/python3/dist-packages/requests_unixsocket/__init__.py", line 1, in <module>
    import requests
  File "/usr/lib/python3/dist-packages/requests/__init__.py", line 43, in <module>
    import urllib3
  File "/usr/lib/python3/dist-packages/urllib3/__init__.py", line 7, in <module>
    from .connectionpool import HTTPConnectionPool, HTTPSConnectionPool, connection_from_url
  File "/usr/lib/python3/dist-packages/urllib3/connectionpool.py", line 11, in <module>
    from .exceptions import (
  File "/usr/lib/python3/dist-packages/urllib3/exceptions.py", line 2, in <module>
    from six.moves.http_client import IncompleteRead as httplib_IncompleteRead
ModuleNotFoundError: No module named 'six'

Original exception was:
Traceback (most recent call last):
  File "manage.py", line 11, in main
    from django.core.management import execute_from_command_line
ModuleNotFoundError: No module named 'django'

The above exception was the direct cause of the following exception:

Traceback (most recent call last):
  File "manage.py", line 22, in <module>
    main()
  File "manage.py", line 13, in main
    raise ImportError(
ImportError: Couldn't import Django. Are you sure it's installed and available on your PYTHONPATH environment variable? Did you forget to activate a virtual environment?
Traceback (most recent call last):
  File "manage.py", line 11, in main
    from django.core.management import execute_from_command_line
ModuleNotFoundError: No module named 'django'

The above exception was the direct cause of the following exception:

Traceback (most recent call last):
  File "manage.py", line 22, in <module>
    main()
  File "manage.py", line 13, in main
    raise ImportError(
ImportError: Couldn't import Django. Are you sure it's installed and available on your PYTHONPATH environment variable? Did you forget to activate a virtual environment?
Error in sys.excepthook:
Traceback (most recent call last):
  File "/usr/lib/python3/dist-packages/apport_python_hook.py", line 72, in apport_excepthook
    from apport.fileutils import likely_packaged, get_recent_crashes
  File "/usr/lib/python3/dist-packages/apport/__init__.py", line 5, in <module>
    from apport.report import Report
  File "/usr/lib/python3/dist-packages/apport/report.py", line 32, in <module>
    import apport.fileutils
  File "/usr/lib/python3/dist-packages/apport/fileutils.py", line 12, in <module>
    import os, glob, subprocess, os.path, time, pwd, sys, requests_unixsocket
  File "/usr/lib/python3/dist-packages/requests_unixsocket/__init__.py", line 1, in <module>
    import requests
  File "/usr/lib/python3/dist-packages/requests/__init__.py", line 43, in <module>
    import urllib3
  File "/usr/lib/python3/dist-packages/urllib3/__init__.py", line 7, in <module>
    from .connectionpool import HTTPConnectionPool, HTTPSConnectionPool, connection_from_url
  File "/usr/lib/python3/dist-packages/urllib3/connectionpool.py", line 11, in <module>
    from .exceptions import (
  File "/usr/lib/python3/dist-packages/urllib3/exceptions.py", line 2, in <module>
    from six.moves.http_client import IncompleteRead as httplib_IncompleteRead
ModuleNotFoundError: No module named 'six'

Original exception was:
Traceback (most recent call last):
  File "manage.py", line 11, in main
    from django.core.management import execute_from_command_line
ModuleNotFoundError: No module named 'django'

The above exception was the direct cause of the following exception:

Traceback (most recent call last):
  File "manage.py", line 22, in <module>
    main()
  File "manage.py", line 13, in main
    raise ImportError(
ImportError: Couldn't import Django. Are you sure it's installed and available on your PYTHONPATH environment variable? Did you forget to activate a virtual environment?
